<?xml version="1.0" encoding="utf-8"?>
<!-- This URDF was automatically created by SolidWorks to URDF Exporter! Originally created by Stephen Brawner (brawner@gmail.com) 
     Commit Version: 1.6.0-4-g7f85cfe  Build Version: 1.6.7995.38578
     For more information, please see http://wiki.ros.org/sw_urdf_exporter -->
<robot
  name="####UR3e_Master_Device">
  <link
    name="base_link">
    <inertial>
      <origin
        xyz="0.016232 0.0045013 -0.059548"
        rpy="0 0 0" />
      <mass
        value="1.1622" />
      <inertia
        ixx="0.0021734"
        ixy="0.00060703"
        ixz="8.5861E-05"
        iyy="0.003053"
        iyz="3.1542E-05"
        izz="0.0049636" />
    </inertial>
    <visual>
      <origin
        xyz="0 0 0"
        rpy="0 0 0" />
      <geometry>
        <mesh
          filename="package://####UR3e_Master_Device/meshes/base_link.STL" />
      </geometry>
      <material
        name="">
        <color
          rgba="0.69804 0.69804 0.69804 1" />
      </material>
    </visual>
    <collision>
      <origin
        xyz="0 0 0"
        rpy="0 0 0" />
      <geometry>
        <mesh
          filename="package://####UR3e_Master_Device/meshes/base_link.STL" />
      </geometry>
    </collision>
  </link>
  <link
    name="L1">
    <inertial>
      <origin
        xyz="-0.028824 -1.682E-06 0.008809"
        rpy="0 0 0" />
      <mass
        value="0.24879" />
      <inertia
        ixx="0.00025445"
        ixy="5.8158E-08"
        ixz="1.902E-05"
        iyy="0.00029997"
        iyz="-1.9743E-08"
        izz="0.00030924" />
    </inertial>
    <visual>
      <origin
        xyz="0 0 0"
        rpy="0 0 0" />
      <geometry>
        <mesh
          filename="package://####UR3e_Master_Device/meshes/L1.STL" />
      </geometry>
      <material
        name="">
        <color
          rgba="0.79216 0.81961 0.93333 1" />
      </material>
    </visual>
    <collision>
      <origin
        xyz="0 0 0"
        rpy="0 0 0" />
      <geometry>
        <mesh
          filename="package://####UR3e_Master_Device/meshes/L1.STL" />
      </geometry>
    </collision>
  </link>
  <joint
    name="J1"
    type="revolute">
    <origin
      xyz="0 0 0"
      rpy="0 0 0" />
    <parent
      link="base_link" />
    <child
      link="L1" />
    <axis
      xyz="0 0 1" />
    <limit
      lower="-3.14"
      upper="3.14"
      effort="50"
      velocity="10" />
  </joint>
  <link
    name="L2">
    <inertial>
      <origin
        xyz="-6.66E-06 -0.062465 0.095606"
        rpy="0 0 0" />
      <mass
        value="0.35913" />
      <inertia
        ixx="0.00031008"
        ixy="-1.0966E-11"
        ixz="-8.6591E-08"
        iyy="0.00015934"
        iyz="2.9881E-05"
        izz="0.0002495" />
    </inertial>
    <visual>
      <origin
        xyz="0 0 0"
        rpy="0 0 0" />
      <geometry>
        <mesh
          filename="package://####UR3e_Master_Device/meshes/L2.STL" />
      </geometry>
      <material
        name="">
        <color
          rgba="0.79216 0.81961 0.93333 1" />
      </material>
    </visual>
    <collision>
      <origin
        xyz="0 0 0"
        rpy="0 0 0" />
      <geometry>
        <mesh
          filename="package://####UR3e_Master_Device/meshes/L2.STL" />
      </geometry>
    </collision>
  </link>
  <joint
    name="J2"
    type="revolute">
    <origin
      xyz="0.019 0 0.05305"
      rpy="-1.5708 0 1.5708" />
    <parent
      link="L1" />
    <child
      link="L2" />
    <axis
      xyz="0 0 -1" />
    <limit
      lower="-3.14"
      upper="3.14"
      effort="50"
      velocity="10" />
  </joint>
  <link
    name="L3">
    <inertial>
      <origin
        xyz="0.073907 -7.305E-05 0.072073"
        rpy="0 0 0" />
      <mass
        value="0.25231" />
      <inertia
        ixx="0.00012274"
        ixy="-1.0941E-07"
        ixz="-1.006E-05"
        iyy="0.00024607"
        iyz="-7.374E-07"
        izz="0.00018887" />
    </inertial>
    <visual>
      <origin
        xyz="0 0 0"
        rpy="0 0 0" />
      <geometry>
        <mesh
          filename="package://####UR3e_Master_Device/meshes/L3.STL" />
      </geometry>
      <material
        name="">
        <color
          rgba="0.43529 0.71765 1 1" />
      </material>
    </visual>
    <collision>
      <origin
        xyz="0 0 0"
        rpy="0 0 0" />
      <geometry>
        <mesh
          filename="package://####UR3e_Master_Device/meshes/L3.STL" />
      </geometry>
    </collision>
  </link>
  <joint
    name="J3"
    type="revolute">
    <origin
      xyz="0 -0.1848 0.0979"
      rpy="3.1416 0 -1.5708" />
    <parent
      link="L2" />
    <child
      link="L3" />
    <axis
      xyz="0 0 1" />
    <limit
      lower="-3.14"
      upper="3.14"
      effort="50"
      velocity="10" />
  </joint>
  <link
    name="L4">
    <inertial>
      <origin
        xyz="-0.00026957 -7.0194E-05 0.030825"
        rpy="0 0 0" />
      <mass
        value="0.063937" />
      <inertia
        ixx="1.777E-05"
        ixy="2.1323E-13"
        ixz="-1.6017E-09"
        iyy="1.7182E-05"
        iyz="-5.244E-15"
        izz="1.2431E-05" />
    </inertial>
    <visual>
      <origin
        xyz="0 0 0"
        rpy="0 0 0" />
      <geometry>
        <mesh
          filename="package://####UR3e_Master_Device/meshes/L4.STL" />
      </geometry>
      <material
        name="">
        <color
          rgba="0.79216 0.81961 0.93333 1" />
      </material>
    </visual>
    <collision>
      <origin
        xyz="0 0 0"
        rpy="0 0 0" />
      <geometry>
        <mesh
          filename="package://####UR3e_Master_Device/meshes/L4.STL" />
      </geometry>
    </collision>
  </link>
  <joint
    name="J4"
    type="revolute">
    <origin
      xyz="0.16493 0 0.06075"
      rpy="-3.1416 0 -3.1416" />
    <parent
      link="L3" />
    <child
      link="L4" />
    <axis
      xyz="0 0 1" />
    <limit
      lower="-3.14"
      upper="3.14"
      effort="50"
      velocity="10" />
  </joint>
  <link
    name="L5">
    <inertial>
      <origin
        xyz="-0.00027584 -7.1825E-05 0.0254"
        rpy="0 0 0" />
      <mass
        value="0.062485" />
      <inertia
        ixx="1.755E-05"
        ixy="1.6906E-12"
        ixz="-1.6017E-09"
        iyy="1.6861E-05"
        iyz="-5.2442E-15"
        izz="1.2024E-05" />
    </inertial>
    <visual>
      <origin
        xyz="0 0 0"
        rpy="0 0 0" />
      <geometry>
        <mesh
          filename="package://####UR3e_Master_Device/meshes/L5.STL" />
      </geometry>
      <material
        name="">
        <color
          rgba="0.79216 0.81961 0.93333 1" />
      </material>
    </visual>
    <collision>
      <origin
        xyz="0 0 0"
        rpy="0 0 0" />
      <geometry>
        <mesh
          filename="package://####UR3e_Master_Device/meshes/L5.STL" />
      </geometry>
    </collision>
  </link>
  <joint
    name="J5"
    type="revolute">
    <origin
      xyz="-0.019 -0.0001 0.048"
      rpy="3.1416 1.5708 0" />
    <parent
      link="L4" />
    <child
      link="L5" />
    <axis
      xyz="0 0 1" />
    <limit
      lower="-3.14"
      upper="3.14"
      effort="50"
      velocity="10" />
  </joint>
  <link
    name="L6">
    <inertial>
      <origin
        xyz="0.017873 1.1057E-06 0.03818"
        rpy="0 0 0" />
      <mass
        value="0.010244" />
      <inertia
        ixx="9.198E-06"
        ixy="-1.0858E-10"
        ixz="-4.5809E-06"
        iyy="1.1566E-05"
        iyz="-1.072E-10"
        izz="3.4797E-06" />
    </inertial>
    <visual>
      <origin
        xyz="0 0 0"
        rpy="0 0 0" />
      <geometry>
        <mesh
          filename="package://####UR3e_Master_Device/meshes/L6.STL" />
      </geometry>
      <material
        name="">
        <color
          rgba="0.79216 0.81961 0.93333 1" />
      </material>
    </visual>
    <collision>
      <origin
        xyz="0 0 0"
        rpy="0 0 0" />
      <geometry>
        <mesh
          filename="package://####UR3e_Master_Device/meshes/L6.STL" />
      </geometry>
    </collision>
  </link>
  <joint
    name="J6"
    type="revolute">
    <origin
      xyz="-0.019 -0.0001 0.04145"
      rpy="3.1416 1.5708 0" />
    <parent
      link="L5" />
    <child
      link="L6" />
    <axis
      xyz="0 0 1" />
    <limit
      lower="-3.14"
      upper="3.14"
      effort="50"
      velocity="10" />
  </joint>
</robot>